
flash_cards3 on ÓÇ† main [!] via üêç v3.10.6 (flash_cards3) took 4m30s
‚ùØ ./manage.py runserver
Watching for file changes with StatReloader
Exception in thread django-main-thread:
Traceback (most recent call last):
  File "/Users/garywhitford/.pyenv/versions/3.10.6/lib/python3.10/threading.py", line 1016, in _bootstrap_inner
    self.run()
  File "/Users/garywhitford/.pyenv/versions/3.10.6/lib/python3.10/threading.py", line 953, in run
    self._target(*self._args, **self._kwargs)
  File "/Users/garywhitford/.local/share/virtualenvs/flash_cards3-XLCU8Rsb/lib/python3.10/site-packages/django/utils/autoreload.py", line 64, in wrapper
    fn(*args, **kwargs)
  File "/Users/garywhitford/.local/share/virtualenvs/flash_cards3-XLCU8Rsb/lib/python3.10/site-packages/django/core/management/commands/runserver.py", line 125, in inner_run
    autoreload.raise_last_exception()
  File "/Users/garywhitford/.local/share/virtualenvs/flash_cards3-XLCU8Rsb/lib/python3.10/site-packages/django/utils/autoreload.py", line 87, in raise_last_exception
    raise _exception[1]
  File "/Users/garywhitford/.local/share/virtualenvs/flash_cards3-XLCU8Rsb/lib/python3.10/site-packages/django/core/management/__init__.py", line 398, in execute
    autoreload.check_errors(django.setup)()
  File "/Users/garywhitford/.local/share/virtualenvs/flash_cards3-XLCU8Rsb/lib/python3.10/site-packages/django/utils/autoreload.py", line 64, in wrapper
    fn(*args, **kwargs)
  File "/Users/garywhitford/.local/share/virtualenvs/flash_cards3-XLCU8Rsb/lib/python3.10/site-packages/django/__init__.py", line 24, in setup
    apps.populate(settings.INSTALLED_APPS)
  File "/Users/garywhitford/.local/share/virtualenvs/flash_cards3-XLCU8Rsb/lib/python3.10/site-packages/django/apps/registry.py", line 91, in populate
    app_config = AppConfig.create(entry)
  File "/Users/garywhitford/.local/share/virtualenvs/flash_cards3-XLCU8Rsb/lib/python3.10/site-packages/django/apps/config.py", line 193, in create
    import_module(entry)
  File "/Users/garywhitford/.pyenv/versions/3.10.6/lib/python3.10/importlib/__init__.py", line 126, in import_module
    return _bootstrap._gcd_import(name[level:], package, level)
  File "<frozen importlib._bootstrap>", line 1050, in _gcd_import
  File "<frozen importlib._bootstrap>", line 1027, in _find_and_load
  File "<frozen importlib._bootstrap>", line 1004, in _find_and_load_unlocked
ModuleNotFoundError: No module named 'index'